<?xml version="1.0"?>

<robot
  name="asrs_arm" xmlns:xacro="http://www.ros.org/wiki/xacro">

  <xacro:property name="PI" value="3.14159265359" />

  <link name="link_1">
    <inertial>
      <origin
        xyz="-0.00049298 0.038467 0.059588"
        rpy="0 0 0" />
      <mass
        value="0.51487" />
      <inertia
        ixx="0.00097956"
        ixy="8.6139E-07"
        ixz="-4.2275E-06"
        iyy="0.00063322"
        iyz="-6.2879E-06"
        izz="0.0014458" />
    </inertial>
    <visual>
      <origin
        xyz="0 0 0"
        rpy="0 0 0" />
      <geometry>
        <mesh
          filename="package://asrs_arm/meshes/link_1.STL" />
      </geometry>
      <material
        name="">
        <color
          rgba="0.8 0.8 0.8 1" />
      </material>
    </visual>
    <collision>
      <origin
        xyz="0 0 0"
        rpy="0 0 0" />
      <geometry>
        <mesh
          filename="package://asrs_arm/meshes/link_1.STL" />
      </geometry>
    </collision>
  </link>

  <link name="link_2">
    <inertial>
      <origin
        xyz="3.3268E-05 0.038546 0.03493"
        rpy="0 0 0" />
      <mass
        value="0.34286" />
      <inertia
        ixx="0.0002982"
        ixy="-1.5865E-08"
        ixz="2.5289E-10"
        iyy="0.00012652"
        iyz="1.9537E-06"
        izz="0.0002767" />
    </inertial>
    <visual>
      <origin
        xyz="0 0 0"
        rpy="0 0 0" />
      <geometry>
        <mesh
          filename="package://asrs_arm/meshes/link_2.STL" />
      </geometry>
      <material
        name="">
        <color
          rgba="0.7 0.7 0.7 1" />
      </material>
    </visual>
    <collision>
      <origin
        xyz="0 0 0"
        rpy="0 0 0" />
      <geometry>
        <mesh
          filename="package://asrs_arm/meshes/link_2.STL" />
      </geometry>
    </collision>
  </link>
  <joint name="joint_1"
    type="revolute">
    <origin
      xyz="0 0 0.0863"
      rpy="0 0 -0.013059" />
    <parent
      link="link_1" />
    <child
      link="link_2" />
    <axis
      xyz="0 0 1" />
    <limit lower="-${PI}" upper="${PI}" effort="0.0" velocity="0.0"/>
  </joint>
  <link name="link_3">
    <inertial>
      <origin
        xyz="-0.00083473 -0.0061303 0.14093"
        rpy="0 0 0" />
      <mass
        value="0.64592" />
      <inertia
        ixx="0.00080618"
        ixy="-8.1896E-10"
        ixz="6.6639E-09"
        iyy="0.00073543"
        iyz="2.8682E-05"
        izz="0.00026191" />
    </inertial>
    <visual>
      <origin
        xyz="0 0 0"
        rpy="0 0 0" />
      <geometry>
        <mesh
          filename="package://asrs_arm/meshes/link_3.STL" />
      </geometry>
      <material
        name="">
        <color
          rgba="0.75 0.75 0.75 1" />
      </material>
    </visual>
    <collision>
      <origin
        xyz="0 0 0"
        rpy="0 0 0" />
      <geometry>
        <mesh
          filename="package://asrs_arm/meshes/link_3.STL" />
      </geometry>
    </collision>
  </link>
  <joint name="joint_2" type="revolute">
    <origin
      xyz="0 0 0.07095"
      rpy="0 0 0" />
    <parent
      link="link_2" />
    <child
      link="link_3" />
    <!-- <axis xyz="-0.99963 -0.027378 0" /> -->
    <axis xyz="-1.0 0.0 0" />
    <limit lower="-${PI/4}" upper="${PI/4}" effort="0.0" velocity="0.0"/>
  </joint>
  <link name="link_4">
    <inertial>
      <origin
        xyz="0.00015398 -0.00014321 0.070552"
        rpy="0 0 0" />
      <mass
        value="0.082446" />
      <inertia
        ixx="7.1121E-05"
        ixy="-1.5741E-09"
        ixz="3.4653E-06"
        iyy="7.2808E-05"
        iyz="5.6573E-09"
        izz="1.4796E-05" />
    </inertial>
    <visual>
      <origin
        xyz="0 0 0"
        rpy="0 0 0" />
      <geometry>
        <mesh
          filename="package://asrs_arm/meshes/link_4.STL" />
      </geometry>
      <material
        name="">
        <color
          rgba="0.7 0.7 0.7 1" />
      </material>
    </visual>
    <collision>
      <origin
        xyz="0 0 0"
        rpy="0 0 0" />
      <geometry>
        <mesh
          filename="package://asrs_arm/meshes/link_4.STL" />
      </geometry>
    </collision>
  </link>
  <joint name="joint_3"
    type="revolute">
    <origin
      xyz="0.0083376 -0.030916 0.24181"
      rpy="0.96329 0.012835 0.018459" />
    <parent
      link="link_3" />
    <child
      link="link_4" />
    <!-- <axis xyz="0.99988 0.015631 0" /> -->
    <axis xyz="1.0 0.0 0" />
    <limit lower="-${PI/4}" upper="${PI/4}" effort="0.0" velocity="0.0"/>
  </joint>

</robot>
